Workbook

Sheet README
A1: KEEL — Agentic HR Operating System
A2: Part 3 — Module & Continuity Matrix
A3: Companion workbook to the Research Report (Part 1), Strategy Document (Part 2) and Investor Deck (Part 4).
A6: PURPOSE | B6: Every HRIS module in scope, with its manual (non-AI) path, its agent capability, its autonomy ceiling, and exactly what happens to it at each level of the Continuity Ladder. This is the artifact that proves the platform runs without AI.
A8: THE BUILD RULE | B8: The manual path ships BEFORE the agent path. Always. Every Transaction Intent an agent can emit must have a corresponding human UI route, verified by automated architectural test in CI.
A10: SHEETS
A11: Continuity Ladder | B11: Definition of levels L0-L4, triggers, and the contractual commitment at each level.
A12: Module Matrix | B12: The complete module inventory. 16 domains. Manual path, agent capability, autonomy ceiling, degradation behaviour, build horizon.
A13: Domain Summary | B13: Live counts by domain and horizon. Formula-driven from Module Matrix.
A14: Agent Portfolio | B14: Every agent, its charter, its accountable owner role, and its hard autonomy ceiling.
A15: Pricing Model | B15: Illustrative unit economics. Blue cells are inputs — edit those. Black cells are formulas.
A17: AUTONOMY CEILING KEY
A18: L0 | B18: Agent may execute autonomously within charter and budget. Human notified; action reversible.
A19: L1 | B19: Agent proposes with deterministic simulation attached. Human approves before execution. HARD CEILING for any decision affecting pay, promotion, discipline or termination — enforced in code, not configuration.
A20: L2 | B20: Agent may draft, summarise, explain or search only. No transaction authority.
A21: n/a | B21: No agent capability. Deterministic module only.
A23: HORIZON KEY
A24: H1 | B24: Months 0-18. The Keel. Deterministic core + payroll-critical modules. AI optional throughout.
A25: H2 | B25: Months 12-36. The Agent Plane. Governed autonomy + talent/performance/learning breadth.
A26: H3 | B26: Months 30-60. The Operating System. Workforce Register, marketplace, planning, agent commerce.
A28: SOURCE NOTE | B28: Module scope was derived from the functional surface of the ten leading SaaS HRIS/HCM suites reviewed in Part 1 (Workday, SAP SuccessFactors, Oracle HCM, ADP, UKG, Dayforce, Rippling, Deel, HiBob/BambooHR/Personio, Darwinbox/Paycom/Paylocity), plus statutory requirements in the Horizon 1 target jurisdictions. Pricing figures are illustrative planning assumptions supplied by the founder, not quotes or forecasts.

Sheet Continuity Ladder
A1: The Continuity Ladder
A2: The published, contractual behaviour of the platform as AI availability degrades. No competitor publishes this.
A4: Level | B4: Name | C4: What operates | D4: Trigger | E4: Customer experience | F4: Contractual commitment
A5: L0 | B5: Autonomous | C5: Agents execute within charter, budget and autonomy ceiling. Every action is a validated deterministic transaction. Human notified; fully reversible from the ledger. | D5: Normal operation, for pre-approved transaction classes only. | E5: Work completes before you ask for it. Notification, not request. | F5: Standard platform SLA. Every L0 action reversible within the retention window.
A6: L1 | B6: Supervised | C6: Agents propose Transaction Intents with a deterministic simulation of the effect attached. Human approves in-flow. Nothing commits without a named approver. | D6: Default for all material decisions. Hard ceiling for pay, promotion, discipline and termination. | E6: One-click approval with full context and projected effect. No black boxes. | F6: Standard platform SLA. Decision Record generated for every approval.
A7: L2 | B7: Assisted | C7: Agents draft, summarise, explain, search and answer. Zero transaction authority. All execution manual. | D7: Elevated risk detected, budget near ceiling, model drift flagged by the evaluation harness, or customer preference. | E7: A capable copilot. All work still gets done, just with more clicks. | F7: Standard platform SLA. Automatic, announced entry — never silent.
A8: L3 | B8: Deterministic | C8: ZERO LLM involvement. The complete HRIS: all 16 domains, all workflows, all calculations, all batch jobs, all reports, all integrations, all statutory filings. Payroll runs. Everything runs. | D8: LLM provider outage, customer kill-switch, legal hold, regulatory order, or customer policy. | E8: A complete, competitive HRIS — functionally indistinguishable from a best-in-class conventional system. Slower, never smaller. | F8: HIGHEST availability commitment of any level, because it has the fewest dependencies. Independently attested annually.
A9: L4 | B9: Continuity | C9: Read-only authoritative core, offline time capture with buffered sync, break-glass approvals under dual control, and emergency payroll from last-good validated state. Signed statutory packs (payroll register, attendance, leave balances, bank instruction files, statutory return drafts) already in the customer's hands. | D9: Regional infrastructure failure, network partition, declared disaster recovery event. | E9: Payroll still runs. People still get paid. The business does not stop. | F9: Statutory packs generated and delivered every cycle whether requested or not. DR procedure tested and evidenced quarterly.
A11: DESIGN RULES THAT MAKE THIS REAL
A12: 1. No capability exists only in the agent plane. Every Transaction Intent type has a manual UI route, verified in CI.
A13: 2. No calculation depends on a model. Payroll, accruals, entitlements, costing, tax and statutory contributions are compiled deterministic policy.
A14: 3. The kill switch is instant, scoped (tenant / entity / branch / module / agent class / single agent) and audited. Sub-second. Two approvers above L1.
A15: 4. L3 is continuously tested, not theoretically available. Weekly automated game-days; monthly L3 window in every customer sandbox; results published to the customer.
A16: 5. L4 has a physical fallback. Signed statutory packs generate every cycle regardless of whether anyone asks for them.
A17: 6. Degradation is announced, never silent. Persistent visible mode banner. The customer always knows the level and the reason.

Sheet Module Matrix
A1: Module & Continuity Matrix
A2: Every module. Manual path first. Agent capability second. Degradation behaviour always specified.
A4: # | B4: Domain | C4: Module | D4: Manual path (L3-complete) | E4: Agent capability | F4: Autonomy ceiling | G4: Behaviour at L3 (no AI) | H4: Horizon
A5: 1 | B5: 1. Foundation & Tenancy | C5: Tenant administration | D5: Full admin console: provisioning, keys, residency, retention, feature flags | E5: Config drift detection; recommends corrections | F5: L1 | G5: Fully operational | H5: H1
A6: 2 | B6: 1. Foundation & Tenancy | C6: Corporate group registry | D6: Group hierarchy modelling with effective dating | E6: None | F6: n/a | G6: Fully operational | H6: H1
A7: 3 | B7: 1. Foundation & Tenancy | C7: Legal entity master | D7: Statutory profile, tax registrations, currency, fiscal calendar per entity | E7: Drafts entity setup from registration documents | F7: L1 | G7: Fully operational | H7: H1
A8: 4 | B8: 1. Foundation & Tenancy | C8: Branch / establishment master | D8: Working-time rules, local registrations, holiday calendars, cost centres | E8: Drafts branch config from a peer branch | F8: L1 | G8: Fully operational | H8: H1
A9: 5 | B9: 1. Foundation & Tenancy | C9: Organisation structure | D9: Versioned, effective-dated org units with as-of reconstruction | E9: Proposes restructure models; simulates cost impact | F9: L1 | G9: Fully operational | H9: H1
A10: 6 | B10: 1. Foundation & Tenancy | C10: Position management | D10: Establishment control, position budgeting, vacancy tracking | E10: Flags over-establishment; proposes reallocation | F10: L1 | G10: Fully operational | H10: H1
A11: 7 | B11: 1. Foundation & Tenancy | C11: Job architecture & catalogue | D11: Job families, levels, descriptions, versioned | E11: Drafts job descriptions; maps to skills ontology | F11: L1 | G11: Fully operational | H11: H1
A12: 8 | B12: 1. Foundation & Tenancy | C12: Grade & band structures | D12: Grade tables, progression rules, effective dating | E12: None | F12: n/a | G12: Fully operational | H12: H1
A13: 9 | B13: 1. Foundation & Tenancy | C13: Cost centre & GL mapping | D13: Multi-dimensional cost allocation rules per entity | E13: Detects unmapped costs; proposes mapping | F13: L1 | G13: Fully operational | H13: H1
A14: 10 | B14: 1. Foundation & Tenancy | C14: Work & holiday calendars | D14: Per entity, branch, shift group; statutory holiday packs | E14: Ingests published holiday gazettes into draft calendars | F14: L1 | G14: Fully operational | H14: H1
A15: 11 | B15: 1. Foundation & Tenancy | C15: Currency & FX | D15: Multi-currency with rate sources and effective dating | E15: None | F15: n/a | G15: Fully operational | H15: H1
A16: 12 | B16: 1. Foundation & Tenancy | C16: RBAC / ABAC authorisation | D16: Role, attribute and scope-based access enforced in the kernel | E16: Detects over-privileged roles; proposes least-privilege | F16: L1 | G16: Fully operational | H16: H1
... A207: 203 | B207: 16. Agent Plane | C207: Customer agent observability | D207: Customer-facing dashboard: what agents did, cost, overrides, incidents | E207: N/A — transparency layer | F207: n/a | G207: Fully operational (historical view) | H207: H2

Sheet Domain Summary
A1: Domain Summary
A2: Live counts from the Module Matrix sheet. All figures are formulas — they update if the matrix changes.
A4: Domain | B4: Modules | C4: Horizon 1 | D4: Horizon 2 | E4: Horizon 3 | F4: No agent (deterministic only) | G4: Hard-capped agent autonomy
A5: 1. Foundation & Tenancy | B5: =COUNTIF('Module Matrix'!$B$5:$B$207,$A5) -> 16 | C5: =COUNTIFS('Module Matrix'!$B$5:$B$207,$A5,'Module Matrix'!$H$5:$H$207,"H1") -> 16 | D5: =COUNTIFS('Module Matrix'!$B$5:$B$207,$A5,'Module Matrix'!$H$5:$H$207,"H2") -> 0 | E5: =COUNTIFS('Module Matrix'!$B$5:$B$207,$A5,'Module Matrix'!$H$5:$H$207,"H3") -> 0 | F5: =COUNTIFS('Module Matrix'!$B$5:$B$207,$A5,'Module Matrix'!$F$5:$F$207,"n/a") -> 4 | G5: =COUNTIFS('Module Matrix'!$B$5:$B$207,$A5,'Module Matrix'!$F$5:$F$207,"*hard cap*") -> 0
A6: 2. Core HR | B6: =COUNTIF('Module Matrix'!$B$5:$B$207,$A6) -> 16 | C6: =COUNTIFS('Module Matrix'!$B$5:$B$207,$A6,'Module Matrix'!$H$5:$H$207,"H1") -> 16 | D6: =COUNTIFS('Module Matrix'!$B$5:$B$207,$A6,'Module Matrix'!$H$5:$H$207,"H2") -> 0 | E6: =COUNTIFS('Module Matrix'!$B$5:$B$207,$A6,'Module Matrix'!$H$5:$H$207,"H3") -> 0 | F6: =COUNTIFS('Module Matrix'!$B$5:$B$207,$A6,'Module Matrix'!$F$5:$F$207,"n/a") -> 1 | G6: =COUNTIFS('Module Matrix'!$B$5:$B$207,$A6,'Module Matrix'!$F$5:$F$207,"*hard cap*") -> 0
A7: 3. Talent Acquisition | B7: =COUNTIF('Module Matrix'!$B$5:$B$207,$A7) -> 15 | C7: =COUNTIFS('Module Matrix'!$B$5:$B$207,$A7,'Module Matrix'!$H$5:$H$207,"H1") -> 0 | D7: =COUNTIFS('Module Matrix'!$B$5:$B$207,$A7,'Module Matrix'!$H$5:$H$207,"H2") -> 15 | E7: =COUNTIFS('Module Matrix'!$B$5:$B$207,$A7,'Module Matrix'!$H$5:$H$207,"H3") -> 0 | F7: =COUNTIFS('Module Matrix'!$B$5:$B$207,$A7,'Module Matrix'!$F$5:$F$207,"n/a") -> 2 | G7: =COUNTIFS('Module Matrix'!$B$5:$B$207,$A7,'Module Matrix'!$F$5:$F$207,"*hard cap*") -> 2
A8: 4. Onboarding & Movement | B8: =COUNTIF('Module Matrix'!$B$5:$B$207,$A8) -> 13 | C8: =COUNTIFS('Module Matrix'!$B$5:$B$207,$A8,'Module Matrix'!$H$5:$H$207,"H1") -> 8 | D8: =COUNTIFS('Module Matrix'!$B$5:$B$207,$A8,'Module Matrix'!$H$5:$H$207,"H2") -> 4 | E8: =COUNTIFS('Module Matrix'!$B$5:$B$207,$A8,'Module Matrix'!$H$5:$H$207,"H3") -> 1 | F8: =COUNTIFS('Module Matrix'!$B$5:$B$207,$A8,'Module Matrix'!$F$5:$F$207,"n/a") -> 1 | G8: =COUNTIFS('Module Matrix'!$B$5:$B$207,$A8,'Module Matrix'!$F$5:$F$207,"*hard cap*") -> 3
A9: 5. Time & Attendance | B9: =COUNTIF('Module Matrix'!$B$5:$B$207,$A9) -> 12 | C9: =COUNTIFS('Module Matrix'!$B$5:$B$207,$A9,'Module Matrix'!$H$5:$H$207,"H1") -> 10 | D9: =COUNTIFS('Module Matrix'!$B$5:$B$207,$A9,'Module Matrix'!$H$5:$H$207,"H2") -> 2 | E9: =COUNTIFS('Module Matrix'!$B$5:$B$207,$A9,'Module Matrix'!$H$5:$H$207,"H3") -> 0 | F9: =COUNTIFS('Module Matrix'!$B$5:$B$207,$A9,'Module Matrix'!$F$5:$F$207,"n/a") -> 2 | G9: =COUNTIFS('Module Matrix'!$B$5:$B$207,$A9,'Module Matrix'!$F$5:$F$207,"*hard cap*") -> 0
A10: 6. Leave & Absence | B10: =COUNTIF('Module Matrix'!$B$5:$B$207,$A10) -> 12 | C10: =COUNTIFS('Module Matrix'!$B$5:$B$207,$A10,'Module Matrix'!$H$5:$H$207,"H1") -> 7 | D10: =COUNTIFS('Module Matrix'!$B$5:$B$207,$A10,'Module Matrix'!$H$5:$H$207,"H2") -> 5 | E10: =COUNTIFS('Module Matrix'!$B$5:$B$207,$A10,'Module Matrix'!$H$5:$H$207,"H3") -> 0 | F10: =COUNTIFS('Module Matrix'!$B$5:$B$207,$A10,'Module Matrix'!$F$5:$F$207,"n/a") -> 0 | G10: =COUNTIFS('Module Matrix'!$B$5:$B$207,$A10,'Module Matrix'!$F$5:$F$207,"*hard cap*") -> 0
A11: 7. Payroll | B11: =COUNTIF('Module Matrix'!$B$5:$B$207,$A11) -> 18 | C11: =COUNTIFS('Module Matrix'!$B$5:$B$207,$A11,'Module Matrix'!$H$5:$H$207,"H1") -> 18 | D11: =COUNTIFS('Module Matrix'!$B$5:$B$207,$A11,'Module Matrix'!$H$5:$H$207,"H2") -> 0 | E11: =COUNTIFS('Module Matrix'!$B$5:$B$207,$A11,'Module Matrix'!$H$5:$H$207,"H3") -> 0 | F11: =COUNTIFS('Module Matrix'!$B$5:$B$207,$A11,'Module Matrix'!$F$5:$F$207,"n/a") -> 4 | G11: =COUNTIFS('Module Matrix'!$B$5:$B$207,$A11,'Module Matrix'!$F$5:$F$207,"*hard cap*") -> 1
A12: 8. Benefits | B12: =COUNTIF('Module Matrix'!$B$5:$B$207,$A12) -> 10 | C12: =COUNTIFS('Module Matrix'!$B$5:$B$207,$A12,'Module Matrix'!$H$5:$H$207,"H1") -> 0 | D12: =COUNTIFS('Module Matrix'!$B$5:$B$207,$A12,'Module Matrix'!$H$5:$H$207,"H2") -> 10 | E12: =COUNTIFS('Module Matrix'!$B$5:$B$207,$A12,'Module Matrix'!$H$5:$H$207,"H3") -> 0 | F12: =COUNTIFS('Module Matrix'!$B$5:$B$207,$A12,'Module Matrix'!$F$5:$F$207,"n/a") -> 0 | G12: =COUNTIFS('Module Matrix'!$B$5:$B$207,$A12,'Module Matrix'!$F$5:$F$207,"*hard cap*") -> 0
A13: 9. Compensation | B13: =COUNTIF('Module Matrix'!$B$5:$B$207,$A13) -> 9 | C13: =COUNTIFS('Module Matrix'!$B$5:$B$207,$A13,'Module Matrix'!$H$5:$H$207,"H1") -> 0 | D13: =COUNTIFS('Module Matrix'!$B$5:$B$207,$A13,'Module Matrix'!$H$5:$H$207,"H2") -> 7 | E13: =COUNTIFS('Module Matrix'!$B$5:$B$207,$A13,'Module Matrix'!$H$5:$H$207,"H3") -> 2 | F13: =COUNTIFS('Module Matrix'!$B$5:$B$207,$A13,'Module Matrix'!$F$5:$F$207,"n/a") -> 0 | G13: =COUNTIFS('Module Matrix'!$B$5:$B$207,$A13,'Module Matrix'!$F$5:$F$207,"*hard cap*") -> 1
A14: 10. Performance | B14: =COUNTIF('Module Matrix'!$B$5:$B$207,$A14) -> 9 | C14: =COUNTIFS('Module Matrix'!$B$5:$B$207,$A14,'Module Matrix'!$H$5:$H$207,"H1") -> 0 | D14: =COUNTIFS('Module Matrix'!$B$5:$B$207,$A14,'Module Matrix'!$H$5:$H$207,"H2") -> 9 | E14: =COUNTIFS('Module Matrix'!$B$5:$B$207,$A14,'Module Matrix'!$H$5:$H$207,"H3") -> 0 | F14: =COUNTIFS('Module Matrix'!$B$5:$B$207,$A14,'Module Matrix'!$F$5:$F$207,"n/a") -> 1 | G14: =COUNTIFS('Module Matrix'!$B$5:$B$207,$A14,'Module Matrix'!$F$5:$F$207,"*hard cap*") -> 3
A15: 11. Learning & Succession | B15: =COUNTIF('Module Matrix'!$B$5:$B$207,$A15) -> 13 | C15: =COUNTIFS('Module Matrix'!$B$5:$B$207,$A15,'Module Matrix'!$H$5:$H$207,"H1") -> 0 | D15: =COUNTIFS('Module Matrix'!$B$5:$B$207,$A15,'Module Matrix'!$H$5:$H$207,"H2") -> 11 | E15: =COUNTIFS('Module Matrix'!$B$5:$B$207,$A15,'Module Matrix'!$H$5:$H$207,"H3") -> 2 | F15: =COUNTIFS('Module Matrix'!$B$5:$B$207,$A15,'Module Matrix'!$F$5:$F$207,"n/a") -> 0 | G15: =COUNTIFS('Module Matrix'!$B$5:$B$207,$A15,'Module Matrix'!$F$5:$F$207,"*hard cap*") -> 2
A16: 12. ER, Compliance & Safety | B16: =COUNTIF('Module Matrix'!$B$5:$B$207,$A16) -> 14 | C16: =COUNTIFS('Module Matrix'!$B$5:$B$207,$A16,'Module Matrix'!$H$5:$H$207,"H1") -> 3 | D16: =COUNTIFS('Module Matrix'!$B$5:$B$207,$A16,'Module Matrix'!$H$5:$H$207,"H2") -> 10 | E16: =COUNTIFS('Module Matrix'!$B$5:$B$207,$A16,'Module Matrix'!$H$5:$H$207,"H3") -> 1 | F16: =COUNTIFS('Module Matrix'!$B$5:$B$207,$A16,'Module Matrix'!$F$5:$F$207,"n/a") -> 2 | G16: =COUNTIFS('Module Matrix'!$B$5:$B$207,$A16,'Module Matrix'!$F$5:$F$207,"*hard cap*") -> 2
... A20: 16. Agent Plane | B20: =COUNTIF('Module Matrix'!$B$5:$B$207,$A20) -> 12 | C20: =COUNTIFS('Module Matrix'!$B$5:$B$207,$A20,'Module Matrix'!$H$5:$H$207,"H1") -> 2 | D20: =COUNTIFS('Module Matrix'!$B$5:$B$207,$A20,'Module Matrix'!$H$5:$H$207,"H2") -> 10 | E20: =COUNTIFS('Module Matrix'!$B$5:$B$207,$A20,'Module Matrix'!$H$5:$H$207,"H3") -> 0 | F20: =COUNTIFS('Module Matrix'!$B$5:$B$207,$A20,'Module Matrix'!$F$5:$F$207,"n/a") -> 12 | G20: =COUNTIFS('Module Matrix'!$B$5:$B$207,$A20,'Module Matrix'!$F$5:$F$207,"*hard cap*") -> 0
A21: TOTAL | B21: =SUM(B5:B20) -> 203 | C21: =SUM(C5:C20) -> 93 | D21: =SUM(D5:D20) -> 99 | E21: =SUM(E5:E20) -> 11 | F21: =SUM(F5:F20) -> 36 | G21: =SUM(G5:G20) -> 15
A23: READING THIS TABLE
A24: Every module in every domain has a complete manual path. That is the point of the table: the 'Horizon' column is a build order, not a capability gate.
A25: 'No agent (deterministic only)' counts modules where no agent capability exists by design — payment initiation, statutory contribution calculation, investigation content, whistleblower channels.
A26: 'Hard-capped agent autonomy' counts modules where the autonomy ceiling is enforced in code and cannot be raised by configuration — anything touching pay, promotion, discipline or termination.
A27: Horizon 1 concentrates on the modules that payroll depends on. A customer can run their entire HR operation on Horizon 1 scope alone.

Sheet Agent Portfolio
A1: Agent Portfolio
A2: Not one assistant — a managed workforce of specialists, each with a charter, a budget and a named accountable human owner.
A4: Group | B4: Agent | C4: Charter | D4: Accountable owner | E4: Autonomy ceiling | F4: Build horizon
A5: Operations | B5: Payroll Preflight Agent | C5: Reconciles time, leave, comp changes and joiners/leavers against the coming cycle; flags anomalies against historical variance; produces a pre-run exception pack. NEVER computes pay. | D5: Payroll Manager | E5: L1 | F5: H2
A6: Operations | B6: Data Integrity Agent | C6: Continuously audits master data against policy and statutory requirements; opens correction transactions for approval. | D6: HR Operations Lead | E6: L1 | F6: H2
A7: Operations | B7: Compliance Watch Agent | C7: Monitors jurisdiction rule changes, maps them to affected entities and populations, drafts policy diffs for human review and compiler validation. | D7: Compliance Lead | E7: L1 | F7: H2
A8: Operations | B8: Document Agent | C8: Generates letters, contracts and statutory forms from templates and ledger data, with citation to every source field. | D8: HR Operations Lead | E8: L0 | F8: H2
A9: Service | B9: Employee Answers Agent | C9: Answers policy, pay, leave and benefits questions from the customer's own policy versions, citing the governing clause and the employee's own data. Never guesses; escalates. | D9: HR Service Lead | E9: L2 | F9: H2
A10: Service | B10: Case Triage Agent | C10: Classifies, routes, prioritises and drafts responses for HR cases. No access to investigation or whistleblower content. | D10: HR Service Lead | E10: L1 | F10: H2
A11: Service | B11: Onboarding Concierge | C11: Orchestrates the joiner journey across systems, chases blockers, answers new-joiner questions. | D11: HR Operations Lead | E11: L0 | F11: H2
A12: Manager | B12: Manager Briefing Agent | C12: Team-level insight, upcoming actions, approval queue with full decision context. | D12: HR Business Partner | E12: L2 | F12: H2
A13: Manager | B13: Scheduling Agent | C13: Proposes rosters against demand, skills, availability, cost and statutory limits. The deterministic solver validates; the manager approves. | D13: Operations Manager | E13: L1 | F13: H2
A14: Manager | B14: Performance Preparation Agent | C14: Assembles evidence for review conversations. Drafts nothing evaluative; the manager authors all judgements. | D14: HR Business Partner | E14: L1 (hard cap) | F14: H2
A15: Talent | B15: Sourcing Agent | C15: Sources and enriches candidate profiles against explicit stated criteria. | D15: Talent Acquisition Lead | E15: L1 | F15: H2
... A22: Platform | B22: Jurisdiction Pack Agent | C22: Drafts pack rules from published legislation for expert review, golden-dataset testing and signing. | D22: Payroll Engineering Lead | E22: L1 | F22: H2
A24: HARD CONSTRAINTS ACROSS THE PORTFOLIO
A25: Screening, performance, promotion, discipline and termination agents are capped at L1 and cannot be raised to L0 by configuration. This is a code-level constraint, not a policy setting.
A26: No agent may act on protected-characteristic data unless the transaction class explicitly requires it and a documented lawful basis is attached.
A27: Every agent output shown to an employee carries a visible AI-involvement disclosure.
A28: No agent has database, payroll engine or workflow engine access. Agents emit typed Transaction Intents to the Control Gate. Nothing else.
A29: Every agent runs in shadow mode — proposing, never executing, scored against human decisions — before any autonomy is granted.

Sheet Pricing Model
A1: Illustrative Unit Economics
A2: Planning assumptions only — not forecasts. Blue cells are inputs; edit those. Black cells are formulas. Yellow fill marks key assumptions.
A4: PRICING INPUTS (per employee per month)
A5: Deterministic Core PEPM — all 16 domains, unlimited manual use | B5: 11
A6: Agent Plane PEPM — flat, not metered, no credits | B6: 6.5
A7: Blended PEPM | B7: =B5+B6 -> 17.5
A9: REFERENCE CUSTOMER
A10: Employees | B10: 4000
A11: Legal entities | B11: 9
A12: Countries | B12: 4
A13: Jurisdiction pack price (per entity per country per year) | B13: 6000
A15: ANNUAL CONTRACT VALUE
A16: Subscription ACV | B16: =B10*B7*12 -> 840000
A17: Jurisdiction pack ACV | B17: =B11*B13 -> 54000
A18: Total ACV | B18: =B16+B17 -> 894000
A19: Effective blended PEPM (all-in) | B19: =B18/B10/12 -> 18.625
A21: COST TO SERVE (% of subscription revenue)
A22: Hosting, storage and deterministic compute | B22: 0.07
A23: Model inference (agent plane) | B23: 0.095
A24: Support and customer success | B24: 0.055
A25: Jurisdiction pack partner revenue share (% of pack ACV) | B25: 0.3
A26: Total cost of revenue | B26: =B16*(B22+B23+B24)+B17*B25 -> 201000
A27: Gross profit | B27: =B18-B26 -> 693000
A28: Gross margin | B28: =IFERROR(B27/B18,0) -> 0.77516779
A30: ACQUISITION & RETENTION
A31: Sales & marketing cost per won customer | B31: 380000
A32: Pre-sale parallel run — delivered free, our GTM wedge | B32: 120000
A33: Fully loaded CAC | B33: =B31+B32 -> 500000
A34: Implementation fee (capped at 0.35x first-year ACV) | B34: =B18*0.35 -> 312900
A35: Implementation delivery cost (as % of fee) | B35: 0.9
A36: Implementation contribution (first year) | B36: =B34*(1-B35) -> 31290
A37: Gross-margin payback on CAC (months) | B37: =IFERROR((B33-B36)/(B27/12),0) -> 8.1161905
A38: Annual gross revenue retention | B38: 0.92
A39: Annual net revenue retention (entity + country + agent-tier expansion) | B39: 1.25
A40: Lifetime cap applied (years) | B40: 7
A41: Implied customer lifetime (lesser of 1/churn and the cap) | B41: =IFERROR(MIN(1/(1-B38),B40),0) -> 7
A42: LTV (gross profit basis, no expansion credit) | B42: =B27*B41 -> 4851000
A43: LTV : CAC | B43: =IFERROR(B42/B33,0) -> 9.702
A45: ASSUMPTIONS & SOURCES
A46: PEPM inputs are founder planning assumptions positioned against the 2026 market benchmark of $15-40 PEPM for mid-market HRIS plus payroll (Part 1, Section 1).
...
